<?xml version="1.0" encoding="utf-8"?>
<!-- This URDF was automatically created by SolidWorks to URDF Exporter! Originally created by Stephen Brawner (brawner@gmail.com) 
     Commit Version: 1.5.1-0-g916b5db  Build Version: 1.5.7152.31018
     For more information, please see http://wiki.ros.org/sw_urdf_exporter -->
<robot
  name="robot_model">

  <link name="base_footprint">
  </link>

  <joint name="base_footprint2base_link" type="fixed">
    <origin xyz="0 0 0.5" rpy="0 0 0"/>
    <parent link="base_footprint"/>
    <child link="base_link"/>
    <axis xyz="0 0 0"/>
  </joint>



  <link
    name="base_link">
    <inertial>
      <origin
        xyz="-0.00893431238084795 -0.00410685218850798 -0.126974415298966"
        rpy="0 0 0" />
      <mass
        value="60.6584049873887" />
      <inertia
        ixx="1.93063361069271"
        ixy="-1.08148006992139E-05"
        ixz="-0.000147443513716209"
        iyy="2.82233947881137"
        iyz="3.80713670524455E-06"
        izz="4.57189084727919" />
    </inertial>
    <visual>
      <origin
        xyz="0 0 0"
        rpy="0 0 0" />
      <geometry>
        <mesh
          filename="package://robot_model/meshes/base_link.STL" />
      </geometry>
      <material
        name="">
        <color
          rgba="0.792156862745098 0.819607843137255 0.933333333333333 1" />
      </material>
    </visual>
    <collision>
      <origin
        xyz="0 0 0"
        rpy="0 0 0" />
      <geometry>
        <mesh
          filename="package://robot_model/meshes/base_link.STL" />
      </geometry>
    </collision>
  </link>
  <link
    name="arm_link0">
    <inertial>
      <origin
        xyz="-1.85892599924298E-07 -0.00115098665543706 0.0188300807306432"
        rpy="0 0 0" />
      <mass
        value="0.655152540803042" />
      <inertia
        ixx="0.00156276083969846"
        ixy="-3.36599648618771E-08"
        ixz="-1.62894681484622E-10"
        iyy="0.00121051829401654"
        iyz="-5.21192954217806E-06"
        izz="0.00262778163467102" />
    </inertial>
    <visual>
      <origin
        xyz="0 0 0"
        rpy="0 0 0" />
      <geometry>
        <mesh
          filename="package://robot_model/meshes/arm_link0.STL" />
      </geometry>
      <material
        name="">
        <color
          rgba="0.752941176470588 0.752941176470588 0.752941176470588 1" />
      </material>
    </visual>
    <collision>
      <origin
        xyz="0 0 0"
        rpy="0 0 0" />
      <geometry>
        <mesh
          filename="package://robot_model/meshes/arm_link0.STL" />
      </geometry>
    </collision>
  </link>
  <joint
    name="arm_joint0"
    type="fixed">
    <origin
      xyz="0.469251651718155 0 0.02"
      rpy="0 0 0" />
    <parent
      link="base_link" />
    <child
      link="arm_link0" />
    <axis
      xyz="0 0 0" />
  </joint>
  <link
    name="arm_link1">
    <inertial>
      <origin
        xyz="6.56593143250062E-06 -0.00217986182575047 -0.00131736708112296"
        rpy="0 0 0" />
      <mass
        value="3.60449209211676" />
      <inertia
        ixx="0.0126654074039028"
        ixy="-2.62089433741316E-07"
        ixz="-1.31830270669369E-07"
        iyy="0.0127154549514285"
        iyz="0.000389410015223875"
        izz="0.0111093940722602" />
    </inertial>
    <visual>
      <origin
        xyz="0 0 0"
        rpy="0 0 0" />
      <geometry>
        <mesh
          filename="package://robot_model/meshes/arm_link1.STL" />
      </geometry>
      <material
        name="">
        <color
          rgba="0.752941176470588 0.752941176470588 0.752941176470588 1" />
      </material>
    </visual>
    <collision>
      <origin
        xyz="0 0 0"
        rpy="0 0 0" />
      <geometry>
        <mesh
          filename="package://robot_model/meshes/arm_link1.STL" />
      </geometry>
    </collision>
  </link>
  <joint
    name="arm_joint1"
    type="revolute">
    <origin
      xyz="0 0 0.14261"
      rpy="0 0 0" />
    <parent
      link="arm_link0" />
    <child
      link="arm_link1" />
    <axis
      xyz="0 0 -1" />
    <limit
      lower="-4.71"
      upper="4.71"
      effort="160"
      velocity="2.09" />
  </joint>
  <link
    name="arm_link2">
    <inertial>
      <origin
        xyz="0.297295860029644 -7.22116929952055E-06 0.181245687804858"
        rpy="0 0 0" />
      <mass
        value="12.2380791922919" />
      <inertia
        ixx="0.0343806292140874"
        ixy="5.21480259951953E-07"
        ixz="-4.57209805955594E-06"
        iyy="0.119109154320758"
        iyz="3.32647013373687E-10"
        izz="0.116279406836501" />
    </inertial>
    <visual>
      <origin
        xyz="0 0 0"
        rpy="0 0 0" />
      <geometry>
        <mesh
          filename="package://robot_model/meshes/arm_link2.STL" />
      </geometry>
      <material
        name="">
        <color
          rgba="0.752941176470588 0.752941176470588 0.752941176470588 1" />
      </material>
    </visual>
    <collision>
      <origin
        xyz="0 0 0"
        rpy="0 0 0" />
      <geometry>
        <mesh
          filename="package://robot_model/meshes/arm_link2.STL" />
      </geometry>
    </collision>
  </link>
  <joint
    name="arm_joint2"
    type="revolute">
    <origin
      xyz="0 0 0"
      rpy="1.5708 -1.5708 0" />
    <parent
      link="arm_link1" />
    <child
      link="arm_link2" />
    <axis
      xyz="0 0 -1" />
    <limit
      lower="-1.48"
      upper="4.63"
      effort="159.24"
      velocity="2.09" />
  </joint>
  <link
    name="arm_link3">
    <inertial>
      <origin
        xyz="0.279323373643594 -2.05269174754497E-05 -0.0168804752155597"
        rpy="0 0 0" />
      <mass
        value="4.95956568648557" />
      <inertia
        ixx="0.0070392604484286"
        ixy="-1.10355720175606E-06"
        ixz="-0.00581502732927868"
        iyy="0.121787936376111"
        iyz="-1.14663299532286E-07"
        izz="0.121496286554897" />
    </inertial>
    <visual>
      <origin
        xyz="0 0 0"
        rpy="0 0 0" />
      <geometry>
        <mesh
          filename="package://robot_model/meshes/arm_link3.STL" />
      </geometry>
      <material
        name="">
        <color
          rgba="0.752941176470588 0.752941176470588 0.752941176470588 1" />
      </material>
    </visual>
    <collision>
      <origin
        xyz="0 0 0"
        rpy="0 0 0" />
      <geometry>
        <mesh
          filename="package://robot_model/meshes/arm_link3.STL" />
      </geometry>
    </collision>
  </link>
  <joint
    name="arm_joint3"
    type="revolute">
    <origin
      xyz="0.59497 -2.3063E-05 0"
      rpy="-3.1416 0 0" />
    <parent
      link="arm_link2" />
    <child
      link="arm_link3" />
    <axis
      xyz="0 0 1" />
    <limit
      lower="-3.05"
      upper="3.05"
      effort="82.38"
      velocity="2.09" />
  </joint>
  <link
    name="arm_link4">
    <inertial>
      <origin
        xyz="-2.96649884686251E-05 -0.002621237975338 0.124278582104445"
        rpy="0 0 0" />
      <mass
        value="0.838886390347174" />
      <inertia
        ixx="0.00145630007823869"
        ixy="-1.63799148217372E-09"
        ixz="6.54274434315661E-09"
        iyy="0.00098615661868495"
        iyz="3.14742670990643E-06"
        izz="0.0014481473926624" />
    </inertial>
    <visual>
      <origin
        xyz="0 0 0"
        rpy="0 0 0" />
      <geometry>
        <mesh
          filename="package://robot_model/meshes/arm_link4.STL" />
      </geometry>
      <material
        name="">
        <color
          rgba="0.752941176470588 0.752941176470588 0.752941176470588 1" />
      </material>
    </visual>
    <collision>
      <origin
        xyz="0 0 0"
        rpy="0 0 0" />
      <geometry>
        <mesh
          filename="package://robot_model/meshes/arm_link4.STL" />
      </geometry>
    </collision>
  </link>
  <joint
    name="arm_joint4"
    type="revolute">
    <origin
      xyz="0.574643539264634 -4.5712785851082E-05 0"
      rpy="-3.14159265358979 0 -1.5707963267949" />
    <parent
      link="arm_link3" />
    <child
      link="arm_link4" />
    <axis
      xyz="0 0 1" />
    <limit
      lower="-1.48"
      upper="4.63"
      effort="13.44"
      velocity="3.14" />
  </joint>
  <link
    name="arm_link5">
    <inertial>
      <origin
        xyz="1.93547867122223E-07 0.12717221555251 -0.0011354400305007"
        rpy="0 0 0" />
      <mass
        value="0.838308466445079" />
      <inertia
        ixx="0.00145558323350275"
        ixy="4.49383625882674E-09"
        ixz="6.58455661563857E-09"
        iyy="0.00100189729657383"
        iyz="-1.22072724248397E-06"
        izz="0.00144948878190334" />
    </inertial>
    <visual>
      <origin
        xyz="0 0 0"
        rpy="0 0 0" />
      <geometry>
        <mesh
          filename="package://robot_model/meshes/arm_link5.STL" />
      </geometry>
      <material
        name="">
        <color
          rgba="0.752941176470588 0.752941176470588 0.752941176470588 1" />
      </material>
    </visual>
    <collision>
      <origin
        xyz="0 0 0"
        rpy="0 0 0" />
      <geometry>
        <mesh
          filename="package://robot_model/meshes/arm_link5.STL" />
      </geometry>
    </collision>
  </link>
  <joint
    name="arm_joint5"
    type="revolute">
    <origin
      xyz="-2.9874E-05 -0.11445 0"
      rpy="1.5708 0 0" />
    <parent
      link="arm_link4" />
    <child
      link="arm_link5" />
    <axis
      xyz="0 0 1" />
    <limit
      lower="-4.71"
      upper="4.71"
      effort="12.06"
      velocity="3.14" />
  </joint>
  <link
    name="arm_link6">
    <inertial>
      <origin
        xyz="-4.913320295441E-05 0.000344891733140895 -0.0420522876754666"
        rpy="0 0 0" />
      <mass
        value="0.18561500243153" />
      <inertia
        ixx="0.000124025995543342"
        ixy="-5.32236134535511E-08"
        ixz="2.56685033045269E-08"
        iyy="0.000124255184258649"
        iyz="-2.96050182378096E-07"
        izz="0.000211261380376879" />
    </inertial>
    <visual>
      <origin
        xyz="0 0 0"
        rpy="0 0 0" />
      <geometry>
        <mesh
          filename="package://robot_model/meshes/arm_link6.STL" />
      </geometry>
      <material
        name="">
        <color
          rgba="0.752941176470588 0.752941176470588 0.752941176470588 1" />
      </material>
    </visual>
    <collision>
      <origin
        xyz="0 0 0"
        rpy="0 0 0" />
      <geometry>
        <mesh
          filename="package://robot_model/meshes/arm_link6.STL" />
      </geometry>
    </collision>
  </link>
  <joint
    name="joint_link6"
    type="revolute">
    <origin
      xyz="0 0 0"
      rpy="1.5707963267949 0 0" />
    <parent
      link="arm_link5" />
    <child
      link="arm_link6" />
    <axis
      xyz="0 0 1" />
    <limit
      lower="-4.71"
      upper="4.71"
      effort="5.46"
      velocity="3.14" />
  </joint>
  <link
    name="turn_link1">
    <inertial>
      <origin
        xyz="4.78495572497906E-06 -0.00533710570631507 -0.0635741590696821"
        rpy="0 0 0" />
      <mass
        value="0.216185282126058" />
      <inertia
        ixx="0.00026246870165202"
        ixy="9.23224201425085E-12"
        ixz="2.5732826757356E-08"
        iyy="0.000263417398814689"
        iyz="1.65492626580328E-06"
        izz="0.00019815950604125" />
    </inertial>
    <visual>
      <origin
        xyz="0 0 0"
        rpy="0 0 0" />
      <geometry>
        <mesh
          filename="package://robot_model/meshes/turn_link1.STL" />
      </geometry>
      <material
        name="">
        <color
          rgba="0.792156862745098 0.819607843137255 0.933333333333333 1" />
      </material>
    </visual>
    <collision>
      <origin
        xyz="0 0 0"
        rpy="0 0 0" />
      <geometry>
        <mesh
          filename="package://robot_model/meshes/turn_link1.STL" />
      </geometry>
    </collision>
  </link>
  <joint
    name="joint_turn1"
    type="revolute">
    <origin
      xyz="0.51025165171796 -0.531954815283265 -0.415396961061793"
      rpy="3.14159265358979 0 0" />
    <parent
      link="base_link" />
    <child
      link="turn_link1" />
    <axis
      xyz="0 0 1" />
    <limit
      lower="-6.28"
      upper="6.28"
      effort="24"
      velocity="392.7" />
  </joint>
  <link
    name="wheel_link1">
    <inertial>
      <origin
        xyz="-9.23771441119214E-07 -1.45099633808154E-07 9.05810189412715E-05"
        rpy="0 0 0" />
      <mass
        value="1.00158503747343" />
      <inertia
        ixx="0.00173475166931306"
        ixy="9.86515466133112E-10"
        ixz="-1.16441874880337E-08"
        iyy="0.00173476885800945"
        iyz="1.80126237976292E-09"
        izz="0.00304652603387399" />
    </inertial>
    <visual>
      <origin
        xyz="0 0 0"
        rpy="0 0 0" />
      <geometry>
        <mesh
          filename="package://robot_model/meshes/wheel_link1.STL" />
      </geometry>
      <material
        name="">
        <color
          rgba="0.792156862745098 0.819607843137255 0.933333333333333 1" />
      </material>
    </visual>
    <collision>
      <origin
        xyz="0 0 0"
        rpy="0 0 0" />
      <geometry>
        <mesh
          filename="package://robot_model/meshes/wheel_link1.STL" />
      </geometry>
    </collision>
  </link>
  <joint
    name="joint_wheel1"
    type="continuous">
    <origin
      xyz="0 0 0"
      rpy="1.5707963267949 1.5707963267949 0" />
    <parent
      link="turn_link1" />
    <child
      link="wheel_link1" />
    <axis
      xyz="0 0 -1" />
  </joint>
  <link
    name="turn_link2">
    <inertial>
      <origin
        xyz="2.83465867445543E-09 0.0200042619428674 -0.0631120030681842"
        rpy="0 0 0" />
      <mass
        value="0.212907250011006" />
      <inertia
        ixx="0.00026151235533371"
        ixy="9.23224334742709E-12"
        ixz="2.9018916968451E-12"
        iyy="0.000262449337362649"
        iyz="-1.65492626580359E-06"
        izz="0.000198093157038937" />
    </inertial>
    <visual>
      <origin
        xyz="0 0 0"
        rpy="0 0 0" />
      <geometry>
        <mesh
          filename="package://robot_model/meshes/turn_link2.STL" />
      </geometry>
      <material
        name="">
        <color
          rgba="0.792156862745098 0.819607843137255 0.933333333333333 1" />
      </material>
    </visual>
    <collision>
      <origin
        xyz="0 0 0"
        rpy="0 0 0" />
      <geometry>
        <mesh
          filename="package://robot_model/meshes/turn_link2.STL" />
      </geometry>
    </collision>
  </link>
  <joint
    name="turn_jiont2"
    type="revolute">
    <origin
      xyz="0.510251651718055 0.531954815283242 -0.415396961061802"
      rpy="-3.14159265358979 0 0" />
    <parent
      link="base_link" />
    <child
      link="turn_link2" />
    <axis
      xyz="0 0 1" />
    <limit
      lower="-6.28"
      upper="6.28"
      effort="24"
      velocity="392.7" />
  </joint>
  <link
    name="wheel_link2">
    <inertial>
      <origin
        xyz="7.83556561412269E-07 8.00142584300723E-07 -0.0108319687597789"
        rpy="0 0 0" />
      <mass
        value="2.70084577274723" />
      <inertia
        ixx="0.00550122561756971"
        ixy="3.26944950597682E-08"
        ixz="-4.5961962270357E-07"
        iyy="0.00550150558695668"
        iyz="8.19279366600689E-08"
        izz="0.00712927200457169" />
    </inertial>
    <visual>
      <origin
        xyz="0 0 0"
        rpy="0 0 0" />
      <geometry>
        <mesh
          filename="package://robot_model/meshes/wheel_link2.STL" />
      </geometry>
      <material
        name="">
        <color
          rgba="0.666666666666667 0.698039215686274 0.768627450980392 1" />
      </material>
    </visual>
    <collision>
      <origin
        xyz="0 0 0"
        rpy="0 0 0" />
      <geometry>
        <mesh
          filename="package://robot_model/meshes/wheel_link2.STL" />
      </geometry>
    </collision>
  </link>
  <joint
    name="joint_wheel2"
    type="continuous">
    <origin
      xyz="0 0 0"
      rpy="1.5707963267949 1.5707963267949 0" />
    <parent
      link="turn_link2" />
    <child
      link="wheel_link2" />
    <axis
      xyz="0 0 -1" />
  </joint>
  <link
    name="turn_link3">
    <inertial>
      <origin
        xyz="-4.78495572542315E-06 0.00533710570631452 -0.0635741590696814"
        rpy="0 0 0" />
      <mass
        value="0.216185282126058" />
      <inertia
        ixx="0.000262468701652019"
        ixy="9.23224218417622E-12"
        ixz="-2.57328267574584E-08"
        iyy="0.000263417398814688"
        iyz="-1.65492626580302E-06"
        izz="0.00019815950604125" />
    </inertial>
    <visual>
      <origin
        xyz="0 0 0"
        rpy="0 0 0" />
      <geometry>
        <mesh
          filename="package://robot_model/meshes/turn_link3.STL" />
      </geometry>
      <material
        name="">
        <color
          rgba="0.792156862745098 0.819607843137255 0.933333333333333 1" />
      </material>
    </visual>
    <collision>
      <origin
        xyz="0 0 0"
        rpy="0 0 0" />
      <geometry>
        <mesh
          filename="package://robot_model/meshes/turn_link3.STL" />
      </geometry>
    </collision>
  </link>
  <joint
    name="joint_turn3"
    type="revolute">
    <origin
      xyz="-0.551748348281648 0.531954815283274 -0.415396961061793"
      rpy="3.14159265358979 0 0" />
    <parent
      link="base_link" />
    <child
      link="turn_link3" />
    <axis
      xyz="0 0 1" />
    <limit
      lower="-6.28"
      upper="6.28"
      effort="24"
      velocity="392.7" />
  </joint>
  <link
    name="wheel_link3">
    <inertial>
      <origin
        xyz="-9.23785491213636E-07 -1.45096786585697E-07 9.05810052858058E-05"
        rpy="0 0 0" />
      <mass
        value="1.00158503687007" />
      <inertia
        ixx="0.00173475166902223"
        ixy="9.86445932143399E-10"
        ixz="-1.16438750737094E-08"
        iyy="0.00173476885738913"
        iyz="1.80119923303238E-09"
        izz="0.00304652603351639" />
    </inertial>
    <visual>
      <origin
        xyz="0 0 0"
        rpy="0 0 0" />
      <geometry>
        <mesh
          filename="package://robot_model/meshes/wheel_link3.STL" />
      </geometry>
      <material
        name="">
        <color
          rgba="0.792156862745098 0.819607843137255 0.933333333333333 1" />
      </material>
    </visual>
    <collision>
      <origin
        xyz="0 0 0"
        rpy="0 0 0" />
      <geometry>
        <mesh
          filename="package://robot_model/meshes/wheel_link3.STL" />
      </geometry>
    </collision>
  </link>
  <joint
    name="joint_wheel3"
    type="continuous">
    <origin
      xyz="0 0 0"
      rpy="1.5707963267949 1.5707963267949 0" />
    <parent
      link="turn_link3" />
    <child
      link="wheel_link3" />
    <axis
      xyz="0 0 -1" />
  </joint>
  <link
    name="turn_link4">
    <inertial>
      <origin
        xyz="-2.83465928507809E-09 -0.0200042619428677 -0.0631120030681847"
        rpy="0 0 0" />
      <mass
        value="0.212907250011006" />
      <inertia
        ixx="0.000261512355333709"
        ixy="9.23224360383132E-12"
        ixz="-2.90189147530696E-12"
        iyy="0.000262449337362648"
        iyz="1.65492626580328E-06"
        izz="0.000198093157038937" />
    </inertial>
    <visual>
      <origin
        xyz="0 0 0"
        rpy="0 0 0" />
      <geometry>
        <mesh
          filename="package://robot_model/meshes/turn_link4.STL" />
      </geometry>
      <material
        name="">
        <color
          rgba="0.792156862745098 0.819607843137255 0.933333333333333 1" />
      </material>
    </visual>
    <collision>
      <origin
        xyz="0 0 0"
        rpy="0 0 0" />
      <geometry>
        <mesh
          filename="package://robot_model/meshes/turn_link4.STL" />
      </geometry>
    </collision>
  </link>
  <joint
    name="joint_turn4"
    type="revolute">
    <origin
      xyz="-0.55175 -0.53195 -0.4154"
      rpy="-3.1416 0 0" />
    <parent
      link="base_link" />
    <child
      link="turn_link4" />
    <axis
      xyz="0 0 1" />
    <limit
      lower="-6.28"
      upper="6.28"
      effort="24"
      velocity="392.7" />
  </joint>
  <link
    name="wheel_link4">
    <inertial>
      <origin
        xyz="7.83556146188857E-07 8.00143050705415E-07 -0.0108319687590166"
        rpy="0 0 0" />
      <mass
        value="2.70084577283169" />
      <inertia
        ixx="0.00550122561765213"
        ixy="3.26945128080932E-08"
        ixz="-4.59619591093497E-07"
        iyy="0.0055015055870359"
        iyz="8.19279026897935E-08"
        izz="0.00712927200460767" />
    </inertial>
    <visual>
      <origin
        xyz="0 0 0"
        rpy="0 0 0" />
      <geometry>
        <mesh
          filename="package://robot_model/meshes/wheel_link4.STL" />
      </geometry>
      <material
        name="">
        <color
          rgba="0.666666666666667 0.698039215686274 0.768627450980392 1" />
      </material>
    </visual>
    <collision>
      <origin
        xyz="0 0 0"
        rpy="0 0 0" />
      <geometry>
        <mesh
          filename="package://robot_model/meshes/wheel_link4.STL" />
      </geometry>
    </collision>
  </link>
  <joint
    name="joint_wheel4"
    type="continuous">
    <origin
      xyz="0 0 0"
      rpy="1.57079632679489 1.5707963267949 0" />
    <parent
      link="turn_link4" />
    <child
      link="wheel_link4" />
    <axis
      xyz="0 0 -1" />
  </joint>
<transmission name="tran_turn1">
  <type>transmission_interface/SimpleTransmission</type>
    <joint name="joint_turn1">
    <hardwareInterface>hardware_interface/EffortJointInterface</hardwareInterface>
    </joint>
    <actuator name="motorturn1">
    <hardwareInterface>hardware_interface/EffortJointInterface</hardwareInterface>
    <mechanicalReduction>1</mechanicalReduction>
    </actuator> 
</transmission>


<transmission name="tran_turn2">
<type>transmission_interface/SimpleTransmission</type>
<joint name="joint_turn2">
<hardwareInterface>hardware_interface/EffortJointInterface</hardwareInterface>
</joint>
<actuator name="motorturn2">
<hardwareInterface>hardware_interface/EffortJointInterface</hardwareInterface>
<mechanicalReduction>1</mechanicalReduction>
</actuator> 
</transmission>


<transmission name="tran_turn3">
<type>transmission_interface/SimpleTransmission</type>
<joint name="joint_turn3">
<hardwareInterface>hardware_interface/EffortJointInterface</hardwareInterface>
</joint>
<actuator name="motorturn3">
<hardwareInterface>hardware_interface/EffortJointInterface</hardwareInterface>
<mechanicalReduction>1</mechanicalReduction>
</actuator> 
</transmission>


<transmission name="tran_turn4">
<type>transmission_interface/SimpleTransmission</type>
<joint name="joint_turn4">
<hardwareInterface>hardware_interface/EffortJointInterface</hardwareInterface>
</joint>
<actuator name="motorturn4">
<hardwareInterface>hardware_interface/EffortJointInterface</hardwareInterface>
<mechanicalReduction>1</mechanicalReduction>
</actuator> 
</transmission>



<transmission name="tran_wheel1">
<type>transmission_interface/SimpleTransmission</type>
<joint name="joint_wheel1">
<hardwareInterface>hardware_interface/EffortJointInterface</hardwareInterface>
</joint>
<actuator name="motorwheel1">
<hardwareInterface>hardware_interface/EffortJointInterface</hardwareInterface>
<mechanicalReduction>1</mechanicalReduction>
</actuator> 
</transmission>



<transmission name="tran_wheel2">
<type>transmission_interface/SimpleTransmission</type>
<joint name="joint_wheel2">
<hardwareInterface>hardware_interface/EffortJointInterface</hardwareInterface>
</joint>
<actuator name="motorwheel2">
<hardwareInterface>hardware_interface/EffortJointInterface</hardwareInterface>
<mechanicalReduction>1</mechanicalReduction>
</actuator> 
</transmission>



<transmission name="tran_wheel3">
<type>transmission_interface/SimpleTransmission</type>
<joint name="joint_wheel3">
<hardwareInterface>hardware_interface/EffortJointInterface</hardwareInterface>
</joint>
<actuator name="motorwheel3">
<hardwareInterface>hardware_interface/EffortJointInterface</hardwareInterface>
<mechanicalReduction>1</mechanicalReduction>
</actuator> 
</transmission>



<transmission name="tran_wheel4">
<type>transmission_interface/SimpleTransmission</type>
<joint name="joint_wheel4">
<hardwareInterface>hardware_interface/EffortJointInterface</hardwareInterface>
</joint>
<actuator name="motorwheel4">
<hardwareInterface>hardware_interface/EffortJointInterface</hardwareInterface>
<mechanicalReduction>1</mechanicalReduction>
</actuator> 
</transmission>

<gazebo>



</gazebo>

<plugin name="gazebo_ros_control" filename="libgazebo_ros_control.so">
<robotNamespace>/agv_sim</robotNamespace>
<robotSimType>gazebo_ros_control/DefaultRobotHWSim</robotSimType>
</plugin>

<!-- <gazebo>
  <plugin name="joint_state_publisher" filename="libgazebo_ros_joint_state_publisher.so">
  <jointName>joint_turn1, joint_turn2, joint_turn3, joint_turn4, 
    joint_wheel1,joint_wheel2,joint_wheel3,joint_wheel4</jointName>
  <updateRate>50.0</updateRate>
  <robotNamespace>/agv_sim</robotNamespace>
  <alwaysOn>true</alwaysOn>
  </plugin>
</gazebo> -->


</robot>